[2025-05-19T22:20:57.237+0000] {taskinstance.py:1159} INFO - Dependencies all met for dep_context=non-requeueable deps ti=<TaskInstance: data_pipeline.create_hive_table scheduled__2025-05-18T22:20:38.382870+00:00 [queued]>
[2025-05-19T22:20:57.250+0000] {taskinstance.py:1159} INFO - Dependencies all met for dep_context=requeueable deps ti=<TaskInstance: data_pipeline.create_hive_table scheduled__2025-05-18T22:20:38.382870+00:00 [queued]>
[2025-05-19T22:20:57.251+0000] {taskinstance.py:1361} INFO - Starting attempt 1 of 2
[2025-05-19T22:20:57.273+0000] {taskinstance.py:1382} INFO - Executing <Task(PythonOperator): create_hive_table> on 2025-05-18 22:20:38.382870+00:00
[2025-05-19T22:20:57.278+0000] {standard_task_runner.py:57} INFO - Started process 394 to run task
[2025-05-19T22:20:57.282+0000] {standard_task_runner.py:84} INFO - Running: ['***', 'tasks', 'run', 'data_pipeline', 'create_hive_table', 'scheduled__2025-05-18T22:20:38.382870+00:00', '--job-id', '31', '--raw', '--subdir', 'DAGS_FOLDER/data_pipeline.py', '--cfg-path', '/tmp/tmpnzvvktt7']
[2025-05-19T22:20:57.285+0000] {standard_task_runner.py:85} INFO - Job 31: Subtask create_hive_table
[2025-05-19T22:20:57.347+0000] {task_command.py:416} INFO - Running <TaskInstance: data_pipeline.create_hive_table scheduled__2025-05-18T22:20:38.382870+00:00 [running]> on host 2dc8e8f16429
[2025-05-19T22:20:57.439+0000] {taskinstance.py:1662} INFO - Exporting env vars: AIRFLOW_CTX_DAG_OWNER='***' AIRFLOW_CTX_DAG_ID='data_pipeline' AIRFLOW_CTX_TASK_ID='create_hive_table' AIRFLOW_CTX_EXECUTION_DATE='2025-05-18T22:20:38.382870+00:00' AIRFLOW_CTX_TRY_NUMBER='1' AIRFLOW_CTX_DAG_RUN_ID='scheduled__2025-05-18T22:20:38.382870+00:00'
[2025-05-19T22:20:57.442+0000] {taskinstance.py:1937} ERROR - Task failed with exception
Traceback (most recent call last):
  File "/home/airflow/.local/lib/python3.8/site-packages/airflow/operators/python.py", line 192, in execute
    return_value = self.execute_callable()
  File "/home/airflow/.local/lib/python3.8/site-packages/airflow/operators/python.py", line 209, in execute_callable
    return self.python_callable(*self.op_args, **self.op_kwargs)
  File "/opt/airflow/dags/data_pipeline.py", line 71, in create_hive_table
    from pyhive import hive
ModuleNotFoundError: No module named 'pyhive'
[2025-05-19T22:20:57.457+0000] {taskinstance.py:1400} INFO - Marking task as UP_FOR_RETRY. dag_id=data_pipeline, task_id=create_hive_table, execution_date=20250518T222038, start_date=20250519T222057, end_date=20250519T222057
[2025-05-19T22:20:57.488+0000] {standard_task_runner.py:104} ERROR - Failed to execute job 31 for task create_hive_table (No module named 'pyhive'; 394)
[2025-05-19T22:20:57.535+0000] {local_task_job_runner.py:228} INFO - Task exited with return code 1
[2025-05-19T22:20:57.566+0000] {taskinstance.py:2778} INFO - 0 downstream tasks scheduled from follow-on schedule check
