[2025-05-20T00:30:15.963+0000] {taskinstance.py:1159} INFO - Dependencies all met for dep_context=non-requeueable deps ti=<TaskInstance: data_pipeline.create_hdfs_sink_connector scheduled__2025-05-19T00:30:10.683323+00:00 [queued]>
[2025-05-20T00:30:16.024+0000] {taskinstance.py:1159} INFO - Dependencies all met for dep_context=requeueable deps ti=<TaskInstance: data_pipeline.create_hdfs_sink_connector scheduled__2025-05-19T00:30:10.683323+00:00 [queued]>
[2025-05-20T00:30:16.026+0000] {taskinstance.py:1361} INFO - Starting attempt 1 of 2
[2025-05-20T00:30:16.118+0000] {taskinstance.py:1382} INFO - Executing <Task(PythonOperator): create_hdfs_sink_connector> on 2025-05-19 00:30:10.683323+00:00
[2025-05-20T00:30:16.145+0000] {standard_task_runner.py:57} INFO - Started process 1075 to run task
[2025-05-20T00:30:16.154+0000] {standard_task_runner.py:84} INFO - Running: ['***', 'tasks', 'run', 'data_pipeline', 'create_hdfs_sink_connector', 'scheduled__2025-05-19T00:30:10.683323+00:00', '--job-id', '46', '--raw', '--subdir', 'DAGS_FOLDER/data_pipeline.py', '--cfg-path', '/tmp/tmpkiozqtja']
[2025-05-20T00:30:16.165+0000] {standard_task_runner.py:85} INFO - Job 46: Subtask create_hdfs_sink_connector
[2025-05-20T00:30:16.374+0000] {task_command.py:416} INFO - Running <TaskInstance: data_pipeline.create_hdfs_sink_connector scheduled__2025-05-19T00:30:10.683323+00:00 [running]> on host 3f580c383c7a
[2025-05-20T00:30:16.773+0000] {taskinstance.py:1662} INFO - Exporting env vars: AIRFLOW_CTX_DAG_OWNER='***' AIRFLOW_CTX_DAG_ID='data_pipeline' AIRFLOW_CTX_TASK_ID='create_hdfs_sink_connector' AIRFLOW_CTX_EXECUTION_DATE='2025-05-19T00:30:10.683323+00:00' AIRFLOW_CTX_TRY_NUMBER='1' AIRFLOW_CTX_DAG_RUN_ID='scheduled__2025-05-19T00:30:10.683323+00:00'
[2025-05-20T00:30:16.819+0000] {taskinstance.py:1937} ERROR - Task failed with exception
Traceback (most recent call last):
  File "/home/airflow/.local/lib/python3.8/site-packages/airflow/operators/python.py", line 192, in execute
    return_value = self.execute_callable()
  File "/home/airflow/.local/lib/python3.8/site-packages/airflow/operators/python.py", line 209, in execute_callable
    return self.python_callable(*self.op_args, **self.op_kwargs)
  File "/opt/airflow/dags/data_pipeline.py", line 68, in create_hdfs_sink_connector
    response.raise_for_status()
  File "/home/airflow/.local/lib/python3.8/site-packages/requests/models.py", line 1021, in raise_for_status
    raise HTTPError(http_error_msg, response=self)
requests.exceptions.HTTPError: 409 Client Error: Conflict for url: http://connect:8083/connectors
[2025-05-20T00:30:16.881+0000] {taskinstance.py:1400} INFO - Marking task as UP_FOR_RETRY. dag_id=data_pipeline, task_id=create_hdfs_sink_connector, execution_date=20250519T003010, start_date=20250520T003015, end_date=20250520T003016
[2025-05-20T00:30:16.946+0000] {standard_task_runner.py:104} ERROR - Failed to execute job 46 for task create_hdfs_sink_connector (409 Client Error: Conflict for url: http://connect:8083/connectors; 1075)
[2025-05-20T00:30:16.974+0000] {local_task_job_runner.py:228} INFO - Task exited with return code 1
[2025-05-20T00:30:17.094+0000] {taskinstance.py:2778} INFO - 0 downstream tasks scheduled from follow-on schedule check
