[2025-05-20T00:30:15.975+0000] {taskinstance.py:1159} INFO - Dependencies all met for dep_context=non-requeueable deps ti=<TaskInstance: data_pipeline.create_hive_table scheduled__2025-05-19T00:30:10.683323+00:00 [queued]>
[2025-05-20T00:30:16.040+0000] {taskinstance.py:1159} INFO - Dependencies all met for dep_context=requeueable deps ti=<TaskInstance: data_pipeline.create_hive_table scheduled__2025-05-19T00:30:10.683323+00:00 [queued]>
[2025-05-20T00:30:16.042+0000] {taskinstance.py:1361} INFO - Starting attempt 1 of 2
[2025-05-20T00:30:16.186+0000] {taskinstance.py:1382} INFO - Executing <Task(PythonOperator): create_hive_table> on 2025-05-19 00:30:10.683323+00:00
[2025-05-20T00:30:16.199+0000] {standard_task_runner.py:57} INFO - Started process 1077 to run task
[2025-05-20T00:30:16.215+0000] {standard_task_runner.py:84} INFO - Running: ['***', 'tasks', 'run', 'data_pipeline', 'create_hive_table', 'scheduled__2025-05-19T00:30:10.683323+00:00', '--job-id', '47', '--raw', '--subdir', 'DAGS_FOLDER/data_pipeline.py', '--cfg-path', '/tmp/tmpl7zwv5ft']
[2025-05-20T00:30:16.224+0000] {standard_task_runner.py:85} INFO - Job 47: Subtask create_hive_table
[2025-05-20T00:30:16.418+0000] {task_command.py:416} INFO - Running <TaskInstance: data_pipeline.create_hive_table scheduled__2025-05-19T00:30:10.683323+00:00 [running]> on host 3f580c383c7a
[2025-05-20T00:30:16.844+0000] {taskinstance.py:1662} INFO - Exporting env vars: AIRFLOW_CTX_DAG_OWNER='***' AIRFLOW_CTX_DAG_ID='data_pipeline' AIRFLOW_CTX_TASK_ID='create_hive_table' AIRFLOW_CTX_EXECUTION_DATE='2025-05-19T00:30:10.683323+00:00' AIRFLOW_CTX_TRY_NUMBER='1' AIRFLOW_CTX_DAG_RUN_ID='scheduled__2025-05-19T00:30:10.683323+00:00'
[2025-05-20T00:30:16.852+0000] {taskinstance.py:1937} ERROR - Task failed with exception
Traceback (most recent call last):
  File "/home/airflow/.local/lib/python3.8/site-packages/airflow/operators/python.py", line 192, in execute
    return_value = self.execute_callable()
  File "/home/airflow/.local/lib/python3.8/site-packages/airflow/operators/python.py", line 209, in execute_callable
    return self.python_callable(*self.op_args, **self.op_kwargs)
  File "/opt/airflow/dags/data_pipeline.py", line 71, in create_hive_table
    from pyhive import hive
ModuleNotFoundError: No module named 'pyhive'
[2025-05-20T00:30:16.909+0000] {taskinstance.py:1400} INFO - Marking task as UP_FOR_RETRY. dag_id=data_pipeline, task_id=create_hive_table, execution_date=20250519T003010, start_date=20250520T003015, end_date=20250520T003016
[2025-05-20T00:30:16.976+0000] {standard_task_runner.py:104} ERROR - Failed to execute job 47 for task create_hive_table (No module named 'pyhive'; 1077)
[2025-05-20T00:30:17.033+0000] {local_task_job_runner.py:228} INFO - Task exited with return code 1
[2025-05-20T00:30:17.271+0000] {taskinstance.py:2778} INFO - 0 downstream tasks scheduled from follow-on schedule check
