[2025-05-20T00:30:09.227+0000] {taskinstance.py:1159} INFO - Dependencies all met for dep_context=non-requeueable deps ti=<TaskInstance: data_pipeline.create_debezium_connector manual__2025-05-18T15:37:18+00:00 [queued]>
[2025-05-20T00:30:09.283+0000] {taskinstance.py:1159} INFO - Dependencies all met for dep_context=requeueable deps ti=<TaskInstance: data_pipeline.create_debezium_connector manual__2025-05-18T15:37:18+00:00 [queued]>
[2025-05-20T00:30:09.286+0000] {taskinstance.py:1361} INFO - Starting attempt 2 of 2
[2025-05-20T00:30:09.352+0000] {taskinstance.py:1382} INFO - Executing <Task(PythonOperator): create_debezium_connector> on 2025-05-18 15:37:18+00:00
[2025-05-20T00:30:09.374+0000] {standard_task_runner.py:57} INFO - Started process 1067 to run task
[2025-05-20T00:30:09.396+0000] {standard_task_runner.py:84} INFO - Running: ['***', 'tasks', 'run', 'data_pipeline', 'create_debezium_connector', 'manual__2025-05-18T15:37:18+00:00', '--job-id', '38', '--raw', '--subdir', 'DAGS_FOLDER/data_pipeline.py', '--cfg-path', '/tmp/tmp_sr6n23p']
[2025-05-20T00:30:09.405+0000] {standard_task_runner.py:85} INFO - Job 38: Subtask create_debezium_connector
[2025-05-20T00:30:09.631+0000] {task_command.py:416} INFO - Running <TaskInstance: data_pipeline.create_debezium_connector manual__2025-05-18T15:37:18+00:00 [running]> on host 3f580c383c7a
[2025-05-20T00:30:10.123+0000] {taskinstance.py:1662} INFO - Exporting env vars: AIRFLOW_CTX_DAG_OWNER='***' AIRFLOW_CTX_DAG_ID='data_pipeline' AIRFLOW_CTX_TASK_ID='create_debezium_connector' AIRFLOW_CTX_EXECUTION_DATE='2025-05-18T15:37:18+00:00' AIRFLOW_CTX_TRY_NUMBER='2' AIRFLOW_CTX_DAG_RUN_ID='manual__2025-05-18T15:37:18+00:00'
[2025-05-20T00:30:10.641+0000] {taskinstance.py:1937} ERROR - Task failed with exception
Traceback (most recent call last):
  File "/home/airflow/.local/lib/python3.8/site-packages/airflow/operators/python.py", line 192, in execute
    return_value = self.execute_callable()
  File "/home/airflow/.local/lib/python3.8/site-packages/airflow/operators/python.py", line 209, in execute_callable
    return self.python_callable(*self.op_args, **self.op_kwargs)
  File "/opt/airflow/dags/data_pipeline.py", line 40, in create_debezium_connector
    response.raise_for_status()
  File "/home/airflow/.local/lib/python3.8/site-packages/requests/models.py", line 1021, in raise_for_status
    raise HTTPError(http_error_msg, response=self)
requests.exceptions.HTTPError: 409 Client Error: Conflict for url: http://connect:8083/connectors
[2025-05-20T00:30:10.680+0000] {taskinstance.py:1400} INFO - Marking task as FAILED. dag_id=data_pipeline, task_id=create_debezium_connector, execution_date=20250518T153718, start_date=20250520T003009, end_date=20250520T003010
[2025-05-20T00:30:10.735+0000] {standard_task_runner.py:104} ERROR - Failed to execute job 38 for task create_debezium_connector (409 Client Error: Conflict for url: http://connect:8083/connectors; 1067)
[2025-05-20T00:30:10.796+0000] {local_task_job_runner.py:228} INFO - Task exited with return code 1
[2025-05-20T00:30:10.911+0000] {taskinstance.py:2778} INFO - 0 downstream tasks scheduled from follow-on schedule check
